[2024-12-24 19:46:09,754] {taskinstance.py:1159} INFO - Dependencies all met for <TaskInstance: TwitterDAG.twitter_datascience manual__2024-12-24T22:46:05.931982+00:00 [queued]>
[2024-12-24 19:46:09,764] {taskinstance.py:1159} INFO - Dependencies all met for <TaskInstance: TwitterDAG.twitter_datascience manual__2024-12-24T22:46:05.931982+00:00 [queued]>
[2024-12-24 19:46:09,764] {taskinstance.py:1356} INFO - 
--------------------------------------------------------------------------------
[2024-12-24 19:46:09,765] {taskinstance.py:1357} INFO - Starting attempt 1 of 1
[2024-12-24 19:46:09,765] {taskinstance.py:1358} INFO - 
--------------------------------------------------------------------------------
[2024-12-24 19:46:09,790] {taskinstance.py:1377} INFO - Executing <Task(TwitterOperator): twitter_datascience> on 2024-12-24 22:46:05.931982+00:00
[2024-12-24 19:46:09,793] {standard_task_runner.py:52} INFO - Started process 982963 to run task
[2024-12-24 19:46:09,809] {standard_task_runner.py:79} INFO - Running: ['airflow', 'tasks', 'run', 'TwitterDAG', 'twitter_datascience', 'manual__2024-12-24T22:46:05.931982+00:00', '--job-id', '14', '--raw', '--subdir', 'DAGS_FOLDER/twitter_dag.py', '--cfg-path', '/tmp/tmp6ipmmej9', '--error-file', '/tmp/tmppzg5zf5e']
[2024-12-24 19:46:09,810] {standard_task_runner.py:80} INFO - Job 14: Subtask twitter_datascience
[2024-12-24 19:46:09,909] {task_command.py:370} INFO - Running <TaskInstance: TwitterDAG.twitter_datascience manual__2024-12-24T22:46:05.931982+00:00 [running]> on host ANDERSON.
[2024-12-24 19:46:09,996] {taskinstance.py:1569} INFO - Exporting the following env vars:
AIRFLOW_CTX_DAG_OWNER=airflow
AIRFLOW_CTX_DAG_ID=TwitterDAG
AIRFLOW_CTX_TASK_ID=twitter_datascience
AIRFLOW_CTX_EXECUTION_DATE=2024-12-24T22:46:05.931982+00:00
AIRFLOW_CTX_TRY_NUMBER=1
AIRFLOW_CTX_DAG_RUN_ID=manual__2024-12-24T22:46:05.931982+00:00
[2024-12-24 19:46:10,011] {taskinstance.py:1889} ERROR - Task failed with exception
Traceback (most recent call last):
  File "/home/dev/curso/airflow_pipeline/operators/twiter_operator.py", line 31, in execute
    for pg in TwiterHook(end_time, start_time, query).run():
  File "/home/dev/curso/airflow_pipeline/hook/twiter_hook.py", line 46, in run
    session = self.get_conn()
  File "/home/dev/curso/ambientevirtual/lib/python3.9/site-packages/airflow/providers/http/hooks/http.py", line 68, in get_conn
    conn = self.get_connection(self.http_conn_id)
  File "/home/dev/curso/ambientevirtual/lib/python3.9/site-packages/airflow/hooks/base.py", line 67, in get_connection
    conn = Connection.get_connection_from_secrets(conn_id)
  File "/home/dev/curso/ambientevirtual/lib/python3.9/site-packages/airflow/models/connection.py", line 430, in get_connection_from_secrets
    raise AirflowNotFoundException(f"The conn_id `{conn_id}` isn't defined")
airflow.exceptions.AirflowNotFoundException: The conn_id `conexao` isn't defined
[2024-12-24 19:46:10,015] {taskinstance.py:1395} INFO - Marking task as FAILED. dag_id=TwitterDAG, task_id=twitter_datascience, execution_date=20241224T224605, start_date=20241224T224609, end_date=20241224T224610
[2024-12-24 19:46:10,029] {standard_task_runner.py:92} ERROR - Failed to execute job 14 for task twitter_datascience (The conn_id `conexao` isn't defined; 982963)
[2024-12-24 19:46:10,065] {local_task_job.py:156} INFO - Task exited with return code 1
[2024-12-24 19:46:10,084] {local_task_job.py:273} INFO - 0 downstream tasks scheduled from follow-on schedule check
