[2024-12-24 19:34:25,550] {taskinstance.py:1159} INFO - Dependencies all met for <TaskInstance: Twitter_dag.Twitter_dataciense manual__2024-12-24T22:34:23.485350+00:00 [queued]>
[2024-12-24 19:34:25,557] {taskinstance.py:1159} INFO - Dependencies all met for <TaskInstance: Twitter_dag.Twitter_dataciense manual__2024-12-24T22:34:23.485350+00:00 [queued]>
[2024-12-24 19:34:25,557] {taskinstance.py:1356} INFO - 
--------------------------------------------------------------------------------
[2024-12-24 19:34:25,557] {taskinstance.py:1357} INFO - Starting attempt 1 of 1
[2024-12-24 19:34:25,557] {taskinstance.py:1358} INFO - 
--------------------------------------------------------------------------------
[2024-12-24 19:34:25,577] {taskinstance.py:1377} INFO - Executing <Task(TwitterOperator): Twitter_dataciense> on 2024-12-24 22:34:23.485350+00:00
[2024-12-24 19:34:25,579] {standard_task_runner.py:52} INFO - Started process 977970 to run task
[2024-12-24 19:34:25,585] {standard_task_runner.py:79} INFO - Running: ['airflow', 'tasks', 'run', 'Twitter_dag', 'Twitter_dataciense', 'manual__2024-12-24T22:34:23.485350+00:00', '--job-id', '13', '--raw', '--subdir', 'DAGS_FOLDER/twitter_dag.py', '--cfg-path', '/tmp/tmp6tu9xpe6', '--error-file', '/tmp/tmphkh_9jxi']
[2024-12-24 19:34:25,586] {standard_task_runner.py:80} INFO - Job 13: Subtask Twitter_dataciense
[2024-12-24 19:34:25,673] {task_command.py:370} INFO - Running <TaskInstance: Twitter_dag.Twitter_dataciense manual__2024-12-24T22:34:23.485350+00:00 [running]> on host ANDERSON.
[2024-12-24 19:34:25,772] {taskinstance.py:1569} INFO - Exporting the following env vars:
AIRFLOW_CTX_DAG_OWNER=airflow
AIRFLOW_CTX_DAG_ID=Twitter_dag
AIRFLOW_CTX_TASK_ID=Twitter_dataciense
AIRFLOW_CTX_EXECUTION_DATE=2024-12-24T22:34:23.485350+00:00
AIRFLOW_CTX_TRY_NUMBER=1
AIRFLOW_CTX_DAG_RUN_ID=manual__2024-12-24T22:34:23.485350+00:00
[2024-12-24 19:34:25,785] {taskinstance.py:1889} ERROR - Task failed with exception
Traceback (most recent call last):
  File "/home/dev/curso/airflow_pipeline/operators/twiter_operator.py", line 31, in execute
    for pg in TwiterHook(end_time, start_time, query).run():
  File "/home/dev/curso/airflow_pipeline/hook/twiter_hook.py", line 46, in run
    session = self.get_conn()
  File "/home/dev/curso/ambientevirtual/lib/python3.9/site-packages/airflow/providers/http/hooks/http.py", line 68, in get_conn
    conn = self.get_connection(self.http_conn_id)
  File "/home/dev/curso/ambientevirtual/lib/python3.9/site-packages/airflow/hooks/base.py", line 67, in get_connection
    conn = Connection.get_connection_from_secrets(conn_id)
  File "/home/dev/curso/ambientevirtual/lib/python3.9/site-packages/airflow/models/connection.py", line 430, in get_connection_from_secrets
    raise AirflowNotFoundException(f"The conn_id `{conn_id}` isn't defined")
airflow.exceptions.AirflowNotFoundException: The conn_id `conexao` isn't defined
[2024-12-24 19:34:25,789] {taskinstance.py:1395} INFO - Marking task as FAILED. dag_id=Twitter_dag, task_id=Twitter_dataciense, execution_date=20241224T223423, start_date=20241224T223425, end_date=20241224T223425
[2024-12-24 19:34:25,806] {standard_task_runner.py:92} ERROR - Failed to execute job 13 for task Twitter_dataciense (The conn_id `conexao` isn't defined; 977970)
[2024-12-24 19:34:25,849] {local_task_job.py:156} INFO - Task exited with return code 1
[2024-12-24 19:34:25,868] {local_task_job.py:273} INFO - 0 downstream tasks scheduled from follow-on schedule check
